import {retryAwareRequest} from './api.js'
import {ClientError} from 'graphql-request'
import {describe, test, vi, expect, beforeEach, afterEach} from 'vitest'

describe('retryAwareRequest', () => {
  beforeEach(() => {
    vi.useFakeTimers()
  })

  afterEach(() => {
    vi.useRealTimers()
  })

  test('handles retries', async () => {
    // First give a network error; then a rate limit with an explicit retry; then an unknown rate limit; then a successful call
    const rateLimitedResponseWithRetry = {
      status: 200,
      errors: [
        {
          extensions: {
            code: '429',
          },
        } as any,
      ],
      headers: new Headers({
        'retry-after': '200',
      }),
    }

    const rateLimitedResponse = {
      status: 200,
      errors: [
        {
          extensions: {
            code: '429',
          },
        } as any,
      ],
      headers: new Headers(),
    }

    const mockRequestFn = vi
      .fn()
      .mockImplementationOnce(() => {
        throw new Error('ENOTFOUND')
      })
      .mockImplementationOnce(() => {
        throw new ClientError(rateLimitedResponseWithRetry, {query: ''})
      })
      .mockImplementationOnce(() => {
        throw new ClientError(rateLimitedResponse, {query: ''})
      })
      .mockImplementationOnce(() => {
        return Promise.resolve({
          status: 200,
          data: {hello: 'world!'},
          headers: new Headers(),
        })
      })
    const mockScheduleDelayFn = vi.fn((fn, delay) => {
      return fn()
    })
    const result = retryAwareRequest(
      {
        request: mockRequestFn,
        url: 'https://example.com',
      },
      undefined,
      undefined,
      {
        defaultDelayMs: 500,
        scheduleDelay: mockScheduleDelayFn,
        enableNetworkLevelRetry: true,
      },
    )
    await vi.runAllTimersAsync()

    await expect(result).resolves.toEqual({
      headers: expect.anything(),
      status: 200,
      data: {hello: 'world!'},
    })

    expect(mockRequestFn).toHaveBeenCalledTimes(4)
    expect(mockScheduleDelayFn).toHaveBeenCalledTimes(2)
    expect(mockScheduleDelayFn).toHaveBeenNthCalledWith(1, expect.anything(), 200)
    expect(mockScheduleDelayFn).toHaveBeenNthCalledWith(2, expect.anything(), 500)
  })

  test('fails after too many retries', async () => {
    // This test gives a false warning from vitest if fake timers are used. It thinks the exception is uncaught.
    vi.useRealTimers()
    const rateLimitedResponse = {
      status: 200,
      errors: [
        {
          extensions: {
            code: '429',
          },
        } as any,
      ],
      headers: new Headers(),
    }
    const mockRequestFn = vi.fn().mockImplementation(() => {
      throw new ClientError(rateLimitedResponse, {query: ''})
    })

    const mockScheduleDelayFn = vi.fn((fn, delay) => {
      return fn()
    })

    const result = retryAwareRequest(
      {
        request: mockRequestFn,
        url: 'https://example.com',
      },
      undefined,
      undefined,
      {
        limitRetriesTo: 7,
        scheduleDelay: mockScheduleDelayFn,
        enableNetworkLevelRetry: true,
      },
    )

    await expect(result).rejects.toThrowError(ClientError)

    expect(mockRequestFn).toHaveBeenCalledTimes(8)
    expect(mockScheduleDelayFn).toHaveBeenCalledTimes(7)
  })

  test('calls unauthorizedHandler when receiving 401', async () => {
    const unauthorizedResponse = {
      status: 401,
      errors: [
        {
          extensions: {
            code: '401',
          },
        } as any,
      ],
      headers: new Headers(),
    }

    const mockRequestFn = vi
      .fn()
      .mockImplementationOnce(() => {
        throw new ClientError(unauthorizedResponse, {query: ''})
      })
      .mockImplementationOnce(() => {
        return Promise.resolve({
          status: 200,
          data: {hello: 'world!'},
          headers: new Headers(),
        })
      })

    const mockUnauthorizedHandler = vi.fn()
    const result = retryAwareRequest(
      {
        request: mockRequestFn,
        url: 'https://example.com',
      },
      undefined,
      mockUnauthorizedHandler,
      {
        scheduleDelay: vi.fn((fn) => fn()),
        enableNetworkLevelRetry: true,
      },
    )
    await vi.runAllTimersAsync()

    await expect(result).resolves.toEqual({
      headers: expect.anything(),
      status: 200,
      data: {hello: 'world!'},
    })

    expect(mockRequestFn).toHaveBeenCalledTimes(2)
    expect(mockUnauthorizedHandler).toHaveBeenCalledTimes(1)
  })

  test('fails on network issue if retries are disabled', async () => {
    // This test gives a false warning from vitest if fake timers are used. It thinks the exception is uncaught.
    vi.useRealTimers()
    const mockRequestFnEnabled = vi
      .fn()
      .mockImplementationOnce(() => {
        // network issue
        throw new Error('ENOTFOUND')
      })
      .mockImplementationOnce(() => {
        // good response -- won't hit this with retries disabled
        return Promise.resolve({
          status: 200,
          data: {hello: 'world!'},
          headers: new Headers(),
        })
      })
    const mockRequestFnDisabled = vi
      .fn()
      .mockImplementationOnce(() => {
        // network issue
        throw new Error('ENOTFOUND')
      })
      .mockImplementationOnce(() => {
        // good response -- won't hit this with retries disabled
        return Promise.resolve({
          status: 200,
          data: {hello: 'world!'},
          headers: new Headers(),
        })
      })
    const mockScheduleDelayFn = vi.fn((fn, delay) => {
      return fn()
    })
    const networkRetryEnabled = retryAwareRequest(
      {
        request: mockRequestFnEnabled,
        url: 'https://example.com',
      },
      undefined,
      undefined,
      {
        defaultDelayMs: 500,
        scheduleDelay: mockScheduleDelayFn,
        enableNetworkLevelRetry: true,
      },
    )

    await expect(networkRetryEnabled).resolves.toEqual({
      headers: expect.anything(),
      status: 200,
      data: {hello: 'world!'},
    })

    const networkRetryDisabled = retryAwareRequest(
      {
        request: mockRequestFnDisabled,
        url: 'https://example.com',
      },
      undefined,
      undefined,
      {
        defaultDelayMs: 500,
        scheduleDelay: mockScheduleDelayFn,
        enableNetworkLevelRetry: false,
      },
    )

    await expect(networkRetryDisabled).rejects.toThrowError('ENOTFOUND')
  })
})
