import {inFunctionContext} from './common.js'
import {load as loadApp} from '../../models/app/loader.js'
import {testApp, testFunctionExtension} from '../../models/app/app.test-data.js'
import {AppInterface} from '../../models/app/app.js'
import {FunctionExtension} from '../../models/app/extensions.js'
import {describe, vi, it, expect, beforeEach} from 'vitest'
import {Config} from '@oclif/core'
import {renderFatalError} from '@shopify/cli-kit/node/ui'
import {joinPath} from '@shopify/cli-kit/node/path'

vi.mock('../../models/app/loader.js')
vi.mock('@shopify/cli-kit/node/ui')

let app: AppInterface
let ourFunction: FunctionExtension

beforeEach(async () => {
  ourFunction = await testFunctionExtension()
  app = testApp({extensions: {ui: [], theme: [], function: [ourFunction]}})
  vi.mocked(loadApp).mockResolvedValue(app)
  vi.mocked(renderFatalError).mockReturnValue()
})

describe('ensure we are within a function context', () => {
  it('runs callback when we are inside a function directory', async () => {
    // Given
    let ranCallback = false

    // When
    await inFunctionContext(
      new Config({root: ''}),
      joinPath(app.directory, 'extensions/my-function'),
      async (_app, _fun) => {
        ranCallback = true
      },
    )

    // Then
    expect(ranCallback).toBe(true)
    expect(renderFatalError).not.toHaveBeenCalled()
  })

  it('displays an error when we are not inside a function directory', async () => {
    // Given
    let ranCallback = false

    // When
    await inFunctionContext(new Config({root: ''}), 'random/dir', async (_app, _fun) => {
      ranCallback = true
    })

    // Then
    expect(ranCallback).toBe(false)
    expect(renderFatalError).toHaveBeenCalledOnce()
  })
})
